reports/tables/phase_e_itch_AAPL_events_sample.csv
event_index,source_message_sequence,source_file_offset,timestamp_ns,time_seconds,message_type,event_type,order_id,old_order_id,size,old_size,price,old_price,execution_price,direction,stock_locate,stock,ask_price_1,ask_size_1,bid_price_1,bid_size_1,ask_price_2,ask_size_2,bid_price_2,bid_size_2,ask_price_3,ask_size_3,bid_price_3,bid_size_3,ask_price_4,ask_size_4,bid_price_4,bid_size_4,ask_price_5,ask_size_5,bid_price_5,bid_size_5,ask_price_6,ask_size_6,bid_price_6,bid_size_6,ask_price_7,ask_size_7,bid_price_7,bid_size_7,ask_price_8,ask_size_8,bid_price_8,bid_size_8,ask_price_9,ask_size_9,bid_price_9,bid_size_9,ask_price_10,ask_size_10,bid_price_10,bid_size_10
25163,10532228,337812985,34200000245396,34200.000245396,D,3,9795461,,100,,163.35,,,-1,14,AAPL,163.34,185.0,163.24,1849.0,163.38,100.0,163.22,100.0,163.39,100.0,163.2,100.0,163.4,200.0,163.16,300.0,163.42,20.0,163.02,20.0,163.46,300.0,163.0,26.0,163.5,29165.0,162.82,100.0,163.6,152.0,162.8,100.0,163.68,21.0,162.6,4.0,163.69,50.0,162.53,2300.0
25164,10532232,337813103,34200000256026,34200.000256026,D,3,9795465,,100,,163.34,,,-1,14,AAPL,163.34,85.0,163.24,1849.0,163.38,100.0,163.22,100.0,163.39,100.0,163.2,100.0,163.4,200.0,163.16,300.0,163.42,20.0,163.02,20.0,163.46,300.0,163.0,26.0,163.5,29165.0,162.82,100.0,163.6,152.0,162.8,100.0,163.68,21.0,162.6,4.0,163.69,50.0,162.53,2300.0
25165,10534800,337903506,34200006086232,34200.006086232,F,1,9806105,,100,,137.13,,,1,14,AAPL,163.34,85.0,163.24,1849.0,163.38,100.0,163.22,100.0,163.39,100.0,163.2,100.0,163.4,200.0,163.16,300.0,163.42,20.0,163.02,20.0,163.46,300.0,163.0,26.0,163.5,29165.0,162.82,100.0,163.6,152.0,162.8,100.0,163.68,21.0,162.6,4.0,163.69,50.0,162.53,2300.0
25166,10534817,337904106,34200006105392,34200.006105392,F,1,9806141,,100,,189.47,,,-1,14,AAPL,163.34,85.0,163.24,1849.0,163.38,100.0,163.22,100.0,163.39,100.0,163.2,100.0,163.4,200.0,163.16,300.0,163.42,20.0,163.02,20.0,163.46,300.0,163.0,26.0,163.5,29165.0,162.82,100.0,163.6,152.0,162.8,100.0,163.68,21.0,162.6,4.0,163.69,50.0,162.53,2300.0
25167,10535949,337944419,34200007269917,34200.007269917,X,2,8817337,,1900,,162.0,,,1,14,AAPL,163.34,85.0,163.24,1849.0,163.38,100.0,163.22,100.0,163.39,100.0,163.2,100.0,163.4,200.0,163.16,300.0,163.42,20.0,163.02,20.0,163.46,300.0,163.0,26.0,163.5,29165.0,162.82,100.0,163.6,152.0,162.8,100.0,163.68,21.0,162.6,4.0,163.69,50.0,162.53,2300.0
25168,10536069,337948796,34200007475109,34200.007475109,D,3,8732569,,200,,156.0,,,1,14,AAPL,163.34,85.0,163.24,1849.0,163.38,100.0,163.22,100.0,163.39,100.0,163.2,100.0,163.4,200.0,163.16,300.0,163.42,20.0,163.02,20.0,163.46,300.0,163.0,26.0,163.5,29165.0,162.82,100.0,163.6,152.0,162.8,100.0,163.68,21.0,162.6,4.0,163.69,50.0,162.53,2300.0
25169,10540900,338128626,34200015403539,34200.015403539,A,1,9818125,,100,,163.38,,,-1,14,AAPL,163.34,85.0,163.24,1849.0,163.38,200.0,163.22,100.0,163.39,100.0,163.2,100.0,163.4,200.0,163.16,300.0,163.42,20.0,163.02,20.0,163.46,300.0,163.0,26.0,163.5,29165.0,162.82,100.0,163.6,152.0,162.8,100.0,163.68,21.0,162.6,4.0,163.69,50.0,162.53,2300.0
25170,10566482,339075730,34200058745380,34200.05874538,A,1,9847961,,100,,153.46,,,1,14,AAPL,163.34,85.0,163.24,1849.0,163.38,200.0,163.22,100.0,163.39,100.0,163.2,100.0,163.4,200.0,163.16,300.0,163.42,20.0,163.02,20.0,163.46,300.0,163.0,26.0,163.5,29165.0,162.82,100.0,163.6,152.0,162.8,100.0,163.68,21.0,162.6,4.0,163.69,50.0,162.53,2300.0
25171,10566495,339076198,34200058771432,34200.058771432,A,1,9847985,,100,,173.13,,,-1,14,AAPL,163.34,85.0,163.24,1849.0,163.38,200.0,163.22,100.0,163.39,100.0,163.2,100.0,163.4,200.0,163.16,300.0,163.42,20.0,163.02,20.0,163.46,300.0,163.0,26.0,163.5,29165.0,162.82,100.0,163.6,152.0,162.8,100.0,163.68,21.0,162.6,4.0,163.69,50.0,162.53,2300.0
25172,10572088,339282883,34200068441198,34200.068441198,A,1,9853241,,100,,163.34,,,-1,14,AAPL,163.34,185.0,163.24,1849.0,163.38,200.0,163.22,100.0,163.39,100.0,163.2,100.0,163.4,200.0,163.16,300.0,163.42,20.0,163.02,20.0,163.46,300.0,163.0,26.0,163.5,29165.0,162.82,100.0,163.6,152.0,162.8,100.0,163.68,21.0,162.6,4.0,163.69,50.0,162.53,2300.0
25173,10572365,339292538,34200068938812,34200.068938812,D,3,9853241,,100,,163.34,,,-1,14,AAPL,163.34,85.0,163.24,1849.0,163.38,200.0,163.22,100.0,163.39,100.0,163.2,100.0,163.4,200.0,163.16,300.0,163.42,20.0,163.02,20.0,163.46,300.0,163.0,26.0,163.5,29165.0,162.82,100.0,163.6,152.0,162.8,100.0,163.68,21.0,162.6,4.0,163.69,50.0,162.53,2300.0
25174,10572367,339292597,34200068950137,34200.068950137,D,3,9818125,,100,,163.38,,,-1,14,AAPL,163.34,85.0,163.24,1849.0,163.38,100.0,163.22,100.0,163.39,100.0,163.2,100.0,163.4,200.0,163.16,300.0,163.42,20.0,163.02,20.0,163.46,300.0,163.0,26.0,163.5,29165.0,162.82,100.0,163.6,152.0,162.8,100.0,163.68,21.0,162.6,4.0,163.69,50.0,162.53,2300.0
25175,10572998,339316199,34200070009111,34200.070009111,A,1,9854889,,250,,209.0,,,-1,14,AAPL,163.34,85.0,163.24,1849.0,163.38,100.0,163.22,100.0,163.39,100.0,163.2,100.0,163.4,200.0,163.16,300.0,163.42,20.0,163.02,20.0,163.46,300.0,163.0,26.0,163.5,29165.0,162.82,100.0,163.6,152.0,162.8,100.0,163.68,21.0,162.6,4.0,163.69,50.0,162.53,2300.0
25176,10573325,339328611,34200070421660,34200.07042166,A,1,9855213,,100,,163.34,,,-1,14,AAPL,163.34,185.0,163.24,1849.0,163.38,100.0,163.22,100.0,163.39,100.0,163.2,100.0,163.4,200.0,163.16,300.0,163.42,20.0,163.02,20.0,163.46,300.0,163.0,26.0,163.5,29165.0,162.82,100.0,163.6,152.0,162.8,100.0,163.68,21.0,162.6,4.0,163.69,50.0,162.53,2300.0
25177,10588174,339878442,34200094363215,34200.094363215,A,1,9867257,,12,,163.12,,,1,14,AAPL,163.34,185.0,163.24,1849.0,163.38,100.0,163.22,100.0,163.39,100.0,163.2,100.0,163.4,200.0,163.16,300.0,163.42,20.0,163.12,12.0,163.46,300.0,163.02,20.0,163.5,29165.0,163.0,26.0,163.6,152.0,162.82,100.0,163.68,21.0,162.8,100.0,163.69,50.0,162.6,4.0
25178,10605445,340528895,34200119405071,34200.119405071,A,1,9885845,,100,,168.35,,,-1,14,AAPL,163.34,185.0,163.24,1849.0,163.38,100.0,163.22,100.0,163.39,100.0,163.2,100.0,163.4,200.0,163.16,300.0,163.42,20.0,163.12,12.0,163.46,300.0,163.02,20.0,163.5,29165.0,163.0,26.0,163.6,152.0,162.82,100.0,163.68,21.0,162.8,100.0,163.69,50.0,162.6,4.0
25179,10605448,340529009,34200119410519,34200.119410519,A,1,9885853,,100,,158.31,,,1,14,AAPL,163.34,185.0,163.24,1849.0,163.38,100.0,163.22,100.0,163.39,100.0,163.2,100.0,163.4,200.0,163.16,300.0,163.42,20.0,163.12,12.0,163.46,300.0,163.02,20.0,163.5,29165.0,163.0,26.0,163.6,152.0,162.82,100.0,163.68,21.0,162.8,100.0,163.69,50.0,162.6,4.0
25180,10605890,340545129,34200120154539,34200.120154539,A,1,9886189,,100,,163.28,,,-1,14,AAPL,163.28,100.0,163.24,1849.0,163.34,185.0,163.22,100.0,163.38,100.0,163.2,100.0,163.39,100.0,163.16,300.0,163.4,200.0,163.12,12.0,163.42,20.0,163.02,20.0,163.46,300.0,163.0,26.0,163.5,29165.0,162.82,100.0,163.6,152.0,162.8,100.0,163.68,21.0,162.6,4.0
25181,10605927,340546574,34200120198973,34200.120198973,A,1,9886285,,100,,168.17,,,-1,14,AAPL,163.28,100.0,163.24,1849.0,163.34,185.0,163.22,100.0,163.38,100.0,163.2,100.0,163.39,100.0,163.16,300.0,163.4,200.0,163.12,12.0,163.42,20.0,163.02,20.0,163.46,300.0,163.0,26.0,163.5,29165.0,162.82,100.0,163.6,152.0,162.8,100.0,163.68,21.0,162.6,4.0
25182,10605931,340546725,34200120209568,34200.120209568,A,1,9886301,,100,,158.35,,,1,14,AAPL,163.28,100.0,163.24,1849.0,163.34,185.0,163.22,100.0,163.38,100.0,163.2,100.0,163.39,100.0,163.16,300.0,163.4,200.0,163.12,12.0,163.42,20.0,163.02,20.0,163.46,300.0,163.0,26.0,163.5,29165.0,162.82,100.0,163.6,152.0,162.8,100.0,163.68,21.0,162.6,4.0
25183,10606151,340554729,34200120609191,34200.120609191,D,3,9886189,,100,,163.28,,,-1,14,AAPL,163.34,185.0,163.24,1849.0,163.38,100.0,163.22,100.0,163.39,100.0,163.2,100.0,163.4,200.0,163.16,300.0,163.42,20.0,163.12,12.0,163.46,300.0,163.02,20.0,163.5,29165.0,163.0,26.0,163.6,152.0,162.82,100.0,163.68,21.0,162.8,100.0,163.69,50.0,162.6,4.0
25184,10606154,340554834,34200120612892,34200.120612892,D,3,9855213,,100,,163.34,,,-1,14,AAPL,163.34,85.0,163.24,1849.0,163.38,100.0,163.22,100.0,163.39,100.0,163.2,100.0,163.4,200.0,163.16,300.0,163.42,20.0,163.12,12.0,163.46,300.0,163.02,20.0,163.5,29165.0,163.0,26.0,163.6,152.0,162.82,100.0,163.68,21.0,162.8,100.0,163.69,50.0,162.6,4.0
